<?xml version="1.0" encoding="utf-8"?>
<!-- =================================================================================== -->
<!-- |    This document was autogenerated by xacro from tango.xacro                    | -->
<!-- |    EDITING THIS FILE BY HAND IS NOT RECOMMENDED                                 | -->
<!-- =================================================================================== -->
<robot name="tango">
  <material name="silver">
    <color rgba="0.700 0.700 0.700 1.000"/>
  </material>
  <material name="black">
    <color rgba="0.0 0.0 0.0 1.0"/>
  </material>
  <material name="blue">
    <color rgba="0.203125 0.23828125 0.28515625 1.0"/>
  </material>
  <material name="green">
    <color rgba="0.0 0.8 0.0 1.0"/>
  </material>
  <material name="grey">
    <color rgba="0.2 0.2 0.2 1.0"/>
  </material>
  <material name="orange">
    <color rgba="1.0 0.423529411765 0.0392156862745 1.0"/>
  </material>
  <material name="brown">
    <color rgba="0.870588235294 0.811764705882 0.764705882353 1.0"/>
  </material>
  <material name="red">
    <color rgba="0.80078125 0.12890625 0.1328125 1.0"/>
  </material>
  <material name="white">
    <color rgba="1.0 1.0 1.0 1.0"/>
  </material>
  <transmission name="Rev15_tran">
    <type>transmission_interface/SimpleTransmission</type>
    <joint name="Rev15">
      <hardwareInterface>hardware_interface/EffortJointInterface</hardwareInterface>
    </joint>
    <actuator name="Rev15_actr">
      <hardwareInterface>hardware_interface/EffortJointInterface</hardwareInterface>
      <mechanicalReduction>1</mechanicalReduction>
    </actuator>
  </transmission>
  <transmission name="Rev16_tran">
    <type>transmission_interface/SimpleTransmission</type>
    <joint name="Rev16">
      <hardwareInterface>hardware_interface/EffortJointInterface</hardwareInterface>
    </joint>
    <actuator name="Rev16_actr">
      <hardwareInterface>hardware_interface/EffortJointInterface</hardwareInterface>
      <mechanicalReduction>1</mechanicalReduction>
    </actuator>
  </transmission>
  <gazebo>
    <plugin filename="libgazebo_ros_control.so" name="control"/>
  </gazebo>
  <gazebo>
    <plugin filename="libgazebo_ros_diff_drive.so" name="differential_drive_controller">
      <legacyMode>false</legacyMode>
      <alwaysOn>true</alwaysOn>
      <updateRate>20</updateRate>
      <leftJoint>Rev15</leftJoint>
      <rightJoint>Rev16</rightJoint>
      <wheelSeparation>0.325</wheelSeparation>
      <wheelDiameter>0.110</wheelDiameter>
      <wheelAcceleration>1.0</wheelAcceleration>
      <torque>0.127</torque>
      <commandTopic>cmd_vel</commandTopic>
      <odometryTopic>odom</odometryTopic>
      <odometryFrame>odom</odometryFrame>
      <robotBaseFrame>base_link</robotBaseFrame>
      <odometrySource>0</odometrySource>
      <publishWheelJointState>true</publishWheelJointState>
    </plugin>
  </gazebo>
  <!-- RpLidar A2 using CPU -->
  <gazebo reference="sensor_laser">
    <sensor name="head_rplidar_sensor" type="ray">
      <pose>0 0 0.06 0 0 0</pose>
      <visualize>false</visualize>
      <update_rate>40</update_rate>
      <ray>
        <scan>
          <horizontal>
            <samples>720</samples>
            <resolution>1</resolution>
            <min_angle>-3.14159265</min_angle>
            <max_angle>3.14159265</max_angle>
          </horizontal>
        </scan>
        <range>
          <min>0.2</min>
          <max>12.0</max>
          <resolution>0.01</resolution>
        </range>
        <noise>
          <type>gaussian</type>
          <mean>0.0</mean>
          <stddev>0.01</stddev>
        </noise>
      </ray>
      <plugin filename="libgazebo_ros_laser.so" name="gazebo_ros_head_rplidar_controller">
        <topicName>/tango/laser/scan</topicName>
        <frameName>sensor_laser</frameName>
      </plugin>
    </sensor>
  </gazebo>
  <gazebo reference="base_link">
    <material>Gazebo/Silver</material>
    <mu1>0.2</mu1>
    <mu2>0.2</mu2>
    <selfCollide>true</selfCollide>
    <gravity>true</gravity>
  </gazebo>
  <gazebo reference="wheel_left_1">
    <material>Gazebo/Silver</material>
    <mu1>0.2</mu1>
    <mu2>0.2</mu2>
    <selfCollide>true</selfCollide>
  </gazebo>
  <gazebo reference="wheel_right_1">
    <material>Gazebo/Silver</material>
    <mu1>0.2</mu1>
    <mu2>0.2</mu2>
    <selfCollide>true</selfCollide>
  </gazebo>
  <link name="dummy_link"/>
  <link name="base_link">
    <inertial>
      <origin rpy="0 0 0" xyz="0.00016953576698395381 -0.003784058871619607 0.04856680225483841"/>
      <mass value="0.9483275242628453"/>
      <inertia ixx="0.010174" ixy="-0.000103" ixz="-4.4e-05" iyy="0.009278" iyz="0.000222" izz="0.015459"/>
    </inertial>
    <visual>
      <origin rpy="0 0 0" xyz="0 0 0"/>
      <geometry>
        <mesh filename="package://tango_description/meshes/base_link.stl" scale="0.001 0.001 0.001"/>
      </geometry>
      <material name="silver"/>
    </visual>
    <collision>
      <origin rpy="0 0 0" xyz="0 0 0"/>
      <geometry>
        <mesh filename="package://tango_description/meshes/base_link.stl" scale="0.001 0.001 0.001"/>
      </geometry>
    </collision>
  </link>
  <link name="sensor_laser">
    <inertial>
      <origin rpy="0 0 0" xyz="0 0 0"/>
      <mass value="1"/>
      <inertia ixx="0.000305583333333" ixy="0" ixz="0" iyy="0.000305583333333" iyz="0" izz="0.0005445"/>
    </inertial>
    <visual>
      <origin rpy="0 0 0" xyz="0 0 0"/>
      <geometry>
        <cylinder length="0.02" radius="0.033"/>
      </geometry>
      <material name="blue"/>
    </visual>
    <collision>
      <origin rpy="0 0 0" xyz="0 0 0"/>
      <geometry>
        <cylinder length="0.02" radius="0.033"/>
      </geometry>
    </collision>
  </link>
  <link name="wheel_left_1">
    <inertial>
      <origin rpy="0 0 0" xyz="-0.16628589477289957 5.602462880330887e-14 -7.487718159456705e-16"/>
      <mass value="0.5462470782161397"/>
      <inertia ixx="0.001184" ixy="-0.0" ixz="0.0" iyy="0.000606" iyz="-0.0" izz="0.000606"/>
    </inertial>
    <visual>
      <origin rpy="0 0 0" xyz="-0.0 -0.0 0.0"/>
      <geometry>
        <mesh filename="package://tango_description/meshes/wheel_left_1.stl" scale="0.001 0.001 0.001"/>
      </geometry>
      <material name="silver"/>
    </visual>
    <collision>
      <origin rpy="0 0 0" xyz="-0.0 -0.0 0.0"/>
      <geometry>
        <mesh filename="package://tango_description/meshes/wheel_left_1.stl" scale="0.001 0.001 0.001"/>
      </geometry>
    </collision>
  </link>
  <link name="wheel_right_1">
    <inertial>
      <origin rpy="0 0 0" xyz="0.16473964498315097 1.3460578998617458e-14 5.271833050320694e-16"/>
      <mass value="0.546247078216141"/>
      <inertia ixx="0.001184" ixy="-0.0" ixz="0.0" iyy="0.000606" iyz="-0.0" izz="0.000606"/>
    </inertial>
    <visual>
      <origin rpy="0 0 0" xyz="-0.0 -0.0 0.0"/>
      <geometry>
        <mesh filename="package://tango_description/meshes/wheel_right_1.stl" scale="0.001 0.001 0.001"/>
      </geometry>
      <material name="silver"/>
    </visual>
    <collision>
      <origin rpy="0 0 0" xyz="-0.0 -0.0 0.0"/>
      <geometry>
        <mesh filename="package://tango_description/meshes/wheel_right_1.stl" scale="0.001 0.001 0.001"/>
      </geometry>
    </collision>
  </link>
  <joint name="dummy_joint" type="fixed">
    <parent link="dummy_link"/>
    <child link="base_link"/>
  </joint>
  <joint name="joint_sensor_laser" type="fixed">
    <origin rpy="0 0 0" xyz="0.0 0.0 0.1496"/>
    <parent link="base_link"/>
    <child link="sensor_laser"/>
  </joint>
  <joint name="Rev15" type="continuous">
    <origin rpy="0 0 0" xyz="0.0 0.0 0.0"/>
    <parent link="base_link"/>
    <child link="wheel_left_1"/>
    <axis xyz="-1.0 0.0 -0.0"/>
  </joint>
  <joint name="Rev16" type="continuous">
    <origin rpy="0 0 0" xyz="0.0 0.0 0.0"/>
    <parent link="base_link"/>
    <child link="wheel_right_1"/>
    <axis xyz="-1.0 -0.0 0.0"/>
  </joint>
</robot>
