<?xml version="1.0" ?>
<robot name="tango" xmlns:xacro="http://www.ros.org/wiki/xacro">

<xacro:include filename="$(find tango_description)/urdf/materials.xacro" />
<xacro:include filename="$(find tango_description)/urdf/tango.trans" />
<xacro:include filename="$(find tango_description)/urdf/tango.gazebo" />

<xacro:macro name="cylinder_inertia" params="mass r l">
  <inertia  ixx="${mass*(3*r*r+l*l)/12}" ixy = "0" ixz = "0"
            iyy="${mass*(3*r*r+l*l)/12}" iyz = "0"
            izz="${mass*(r*r)/2}" />
</xacro:macro>

<link name="dummy_link" />

<link name="base_link">
  <inertial>
    <origin rpy="0 0 0" xyz="0.00016953576698395381 -0.003784058871619607 0.04856680225483841"/>
    <mass value="0.9483275242628453"/>
    <inertia ixx="0.010174" ixy="-0.000103" ixz="-4.4e-05" iyy="0.009278" iyz="0.000222" izz="0.015459"/>
  </inertial>
  <visual>
    <origin rpy="0 0 0" xyz="0 0 0"/>
    <geometry>
      <mesh filename="package://tango_description/meshes/base_link.stl" scale="0.001 0.001 0.001"/>
    </geometry>
    <material name="silver"/>
  </visual>
  <collision>
    <origin rpy="0 0 0" xyz="0 0 0"/>
    <geometry>
      <mesh filename="package://tango_description/meshes/base_link.stl" scale="0.001 0.001 0.001"/>
    </geometry>
  </collision>
</link>

<link name="sensor_laser">
  <inertial>
      <origin xyz="0 0 0" rpy="0 0 0" />
      <mass value="1" />
      <xacro:cylinder_inertia mass="1" r="0.033" l="0.02" />
  </inertial>
  <visual>
      <origin xyz="0 0 0" rpy="0 0 0" />
      <geometry>
      <cylinder radius="0.033" length="0.02"/>
      </geometry>
      <material name="blue" />
  </visual>
  <collision>
      <origin xyz="0 0 0" rpy="0 0 0"/>
      <geometry>
      <cylinder radius="0.033" length="0.02"/>
      </geometry>
  </collision>
</link>

<link name="wheel_left_1">
  <inertial>
    <origin rpy="0 0 0" xyz="-0.16628589477289957 5.602462880330887e-14 -7.487718159456705e-16"/>
    <mass value="0.5462470782161397"/>
    <inertia ixx="0.001184" ixy="-0.0" ixz="0.0" iyy="0.000606" iyz="-0.0" izz="0.000606"/>
  </inertial>
  <visual>
    <origin rpy="0 0 0" xyz="-0.0 -0.0 0.0"/>
    <geometry>
      <mesh filename="package://tango_description/meshes/wheel_left_1.stl" scale="0.001 0.001 0.001"/>
    </geometry>
    <material name="silver"/>
  </visual>
  <collision>
    <origin rpy="0 0 0" xyz="-0.0 -0.0 0.0"/>
    <geometry>
      <mesh filename="package://tango_description/meshes/wheel_left_1.stl" scale="0.001 0.001 0.001"/>
    </geometry>
  </collision>
</link>

<link name="wheel_right_1">
  <inertial>
    <origin rpy="0 0 0" xyz="0.16473964498315097 1.3460578998617458e-14 5.271833050320694e-16"/>
    <mass value="0.546247078216141"/>
    <inertia ixx="0.001184" ixy="-0.0" ixz="0.0" iyy="0.000606" iyz="-0.0" izz="0.000606"/>
  </inertial>
  <visual>
    <origin rpy="0 0 0" xyz="-0.0 -0.0 0.0"/>
    <geometry>
      <mesh filename="package://tango_description/meshes/wheel_right_1.stl" scale="0.001 0.001 0.001"/>
    </geometry>
    <material name="silver"/>
  </visual>
  <collision>
    <origin rpy="0 0 0" xyz="-0.0 -0.0 0.0"/>
    <geometry>
      <mesh filename="package://tango_description/meshes/wheel_right_1.stl" scale="0.001 0.001 0.001"/>
    </geometry>
  </collision>
</link>


<joint name="dummy_joint" type="fixed">
<parent link="dummy_link"/>
<child link="base_link"/>
</joint>

<joint name="joint_sensor_laser" type="fixed">
    <origin xyz="0.0 0.0 0.1496" rpy="0 0 0"/>
    <parent link="base_link"/>
    <child link="sensor_laser"/>
</joint>

<joint name="Rev15" type="continuous">
  <origin rpy="0 0 0" xyz="0.0 0.0 0.0"/>
  <parent link="base_link"/>
  <child link="wheel_left_1"/>
  <axis xyz="-1.0 0.0 -0.0"/>
</joint>

<joint name="Rev16" type="continuous">
  <origin rpy="0 0 0" xyz="0.0 0.0 0.0"/>
  <parent link="base_link"/>
  <child link="wheel_right_1"/>
  <axis xyz="-1.0 -0.0 0.0"/>
</joint>

</robot>
